<testsuite name="debug.debug.WebAuthn Debug" tests="1" errors="1" failures="0" skipped="0" time="1.816583" timestamp="2025-07-14T15:04:57.377889" hostname="LAP-BE-DOCKXBE1"><testcase classname="debug.debug.WebAuthn Debug" name="Debug registration flow" status="failed" time="1.816583"><error type="NoSuchContextException" message="Message: No such context found.&#10;Stacktrace:&#10;NoSuchContextError: No such context found.&#10;    at AndroidUiautomator2Driver.setContext (C:\Users\x_dockxbe1\.appium\node_modules\appium-uiautomator2-driver\node_modules\appium-android-driver\lib\commands\context\exports.js:66:11)">
<![CDATA[
Failing step: Given I enter username "debug_test" ... failed in 0.314s
Location: features/debug/debug.feature:10
Traceback (most recent call last):
  File "C:\Users\x_dockxbe1\Downloads\mobiletests\mobiletests-master\.venv\Lib\site-packages\behave\model.py", line 1329, in run
    match.run(runner.context)
  File "C:\Users\x_dockxbe1\Downloads\mobiletests\mobiletests-master\.venv\Lib\site-packages\behave\matchers.py", line 98, in run
    self.func(context, *args, **kwargs)
  File "features\steps\webauthn_steps.py", line 41, in step_enter_username
    context.wa_util.fill_username(username=username)
  File "C:\Users\x_dockxbe1\Downloads\mobiletests\mobiletests-master\webauthn\webauthn_util.py", line 18, in fill_username
    self.controller.find_element(WebAuthnLocators.USERNAME_BOX).send_keys(username)
    ^^^^^^^^^^^^^^^^^^^^^^^^^^^^^^^^^^^^^^^^^^^^^^^^^^^^^^^^^^^
  File "C:\Users\x_dockxbe1\Downloads\mobiletests\mobiletests-master\shared\appium_util.py", line 55, in find_element
    self.switch_context(locator.context)
  File "C:\Users\x_dockxbe1\Downloads\mobiletests\mobiletests-master\shared\appium_util.py", line 50, in switch_context
    self.driver.switch_to.context(context.value)
  File "C:\Users\x_dockxbe1\Downloads\mobiletests\mobiletests-master\.venv\Lib\site-packages\appium\webdriver\switch_to.py", line 40, in context
    self._driver.execute(MobileCommand.SWITCH_TO_CONTEXT, {'name': context_name})
  File "C:\Users\x_dockxbe1\Downloads\mobiletests\mobiletests-master\.venv\Lib\site-packages\selenium\webdriver\remote\webdriver.py", line 454, in execute
    self.error_handler.check_response(response)
  File "C:\Users\x_dockxbe1\Downloads\mobiletests\mobiletests-master\.venv\Lib\site-packages\appium\webdriver\errorhandler.py", line 125, in check_response
    raise exception_class(msg=message, stacktrace=format_stacktrace(stacktrace))
appium.common.exceptions.NoSuchContextException: Message: No such context found.
Stacktrace:
NoSuchContextError: No such context found.
    at AndroidUiautomator2Driver.setContext (C:\Users\x_dockxbe1\.appium\node_modules\appium-uiautomator2-driver\node_modules\appium-android-driver\lib\commands\context\exports.js:66:11)

Captured logging:
INFO     builtins: DIGIPASS FX7 device verified as connected
INFO     builtins: Navigating to WebAuthn registration page
INFO     builtins: Entering username: debug_test]]>
</error><system-out>
<![CDATA[
@scenario.begin

  @debug @hardware @registration
  Scenario: Debug registration flow
    Given I have a DIGIPASS FX7 device connected ... passed in 0.000s
    And I am on the WebAuthn registration page ... passed in 1.502s
    Given I enter username "debug_test" ... failed in 0.314s
    When I click the register button with debug ... skipped in 0.000s
    And I wait for hardware authenticator popup ... skipped in 0.000s
    Then the registration should succeed ... skipped in 0.000s

@scenario.end
--------------------------------------------------------------------------------
]]>
</system-out></testcase></testsuite>